WARNING:googleapiclient.discovery_cache:file_cache is unavailable when using oauth2client >= 4.0.0 or google-auth
Traceback (most recent call last):
  File "C:\Users\sshho\anaconda3\envs\GmailAPI\lib\site-packages\googleapiclient\discovery_cache\file_cache.py", line 33, in <module>
    from oauth2client.contrib.locked_file import LockedFile
ModuleNotFoundError: No module named 'oauth2client'

During handling of the above exception, another exception occurred:

Traceback (most recent call last):
  File "C:\Users\sshho\anaconda3\envs\GmailAPI\lib\site-packages\googleapiclient\discovery_cache\file_cache.py", line 37, in <module>
    from oauth2client.locked_file import LockedFile
ModuleNotFoundError: No module named 'oauth2client'

During handling of the above exception, another exception occurred:

Traceback (most recent call last):
  File "C:\Users\sshho\anaconda3\envs\GmailAPI\lib\site-packages\googleapiclient\discovery_cache\__init__.py", line 44, in autodetect
    from . import file_cache
  File "C:\Users\sshho\anaconda3\envs\GmailAPI\lib\site-packages\googleapiclient\discovery_cache\file_cache.py", line 40, in <module>
    raise ImportError(
ImportError: file_cache is unavailable when using oauth2client >= 4.0.0 or google-auth
DEBUG:googleapiclient.discovery:URL being requested: GET https://www.googleapis.com/discovery/v1/apis/gmail/v1/rest
INFO:root:connected to Gmail API
DEBUG:googleapiclient.discovery:URL being requested: GET https://gmail.googleapis.com/gmail/v1/users/me/messages?labelIds=INBOX&alt=json
DEBUG:googleapiclient.discovery:URL being requested: GET https://gmail.googleapis.com/gmail/v1/users/me/messages/17589ab2ce4e1fc4?alt=json
DEBUG:googleapiclient.discovery:URL being requested: GET https://gmail.googleapis.com/gmail/v1/users/me/messages/17589601e24d1b0a?alt=json
DEBUG:googleapiclient.discovery:URL being requested: GET https://gmail.googleapis.com/gmail/v1/users/me/messages/17589488cedc2852?alt=json
DEBUG:googleapiclient.discovery:URL being requested: GET https://gmail.googleapis.com/gmail/v1/users/me/messages/175894336dfcbb46?alt=json
WARNING:googleapiclient.discovery_cache:file_cache is unavailable when using oauth2client >= 4.0.0 or google-auth
Traceback (most recent call last):
  File "C:\Users\sshho\anaconda3\envs\GmailAPI\lib\site-packages\googleapiclient\discovery_cache\file_cache.py", line 33, in <module>
    from oauth2client.contrib.locked_file import LockedFile
ModuleNotFoundError: No module named 'oauth2client'

During handling of the above exception, another exception occurred:

Traceback (most recent call last):
  File "C:\Users\sshho\anaconda3\envs\GmailAPI\lib\site-packages\googleapiclient\discovery_cache\file_cache.py", line 37, in <module>
    from oauth2client.locked_file import LockedFile
ModuleNotFoundError: No module named 'oauth2client'

During handling of the above exception, another exception occurred:

Traceback (most recent call last):
  File "C:\Users\sshho\anaconda3\envs\GmailAPI\lib\site-packages\googleapiclient\discovery_cache\__init__.py", line 44, in autodetect
    from . import file_cache
  File "C:\Users\sshho\anaconda3\envs\GmailAPI\lib\site-packages\googleapiclient\discovery_cache\file_cache.py", line 40, in <module>
    raise ImportError(
ImportError: file_cache is unavailable when using oauth2client >= 4.0.0 or google-auth
DEBUG:googleapiclient.discovery:URL being requested: GET https://www.googleapis.com/discovery/v1/apis/gmail/v1/rest
INFO:root:connected to Gmail API
DEBUG:googleapiclient.discovery:URL being requested: GET https://gmail.googleapis.com/gmail/v1/users/me/messages?labelIds=INBOX&alt=json
DEBUG:googleapiclient.discovery:URL being requested: GET https://gmail.googleapis.com/gmail/v1/users/me/messages/17589ab2ce4e1fc4?alt=json
DEBUG:googleapiclient.discovery:URL being requested: GET https://gmail.googleapis.com/gmail/v1/users/me/messages/17589601e24d1b0a?alt=json
DEBUG:googleapiclient.discovery:URL being requested: GET https://gmail.googleapis.com/gmail/v1/users/me/messages/17589488cedc2852?alt=json
DEBUG:googleapiclient.discovery:URL being requested: GET https://gmail.googleapis.com/gmail/v1/users/me/messages/175894336dfcbb46?alt=json
WARNING:googleapiclient.discovery_cache:file_cache is unavailable when using oauth2client >= 4.0.0 or google-auth
Traceback (most recent call last):
  File "C:\Users\sshho\anaconda3\envs\GmailAPI\lib\site-packages\googleapiclient\discovery_cache\file_cache.py", line 33, in <module>
    from oauth2client.contrib.locked_file import LockedFile
ModuleNotFoundError: No module named 'oauth2client'

During handling of the above exception, another exception occurred:

Traceback (most recent call last):
  File "C:\Users\sshho\anaconda3\envs\GmailAPI\lib\site-packages\googleapiclient\discovery_cache\file_cache.py", line 37, in <module>
    from oauth2client.locked_file import LockedFile
ModuleNotFoundError: No module named 'oauth2client'

During handling of the above exception, another exception occurred:

Traceback (most recent call last):
  File "C:\Users\sshho\anaconda3\envs\GmailAPI\lib\site-packages\googleapiclient\discovery_cache\__init__.py", line 44, in autodetect
    from . import file_cache
  File "C:\Users\sshho\anaconda3\envs\GmailAPI\lib\site-packages\googleapiclient\discovery_cache\file_cache.py", line 40, in <module>
    raise ImportError(
ImportError: file_cache is unavailable when using oauth2client >= 4.0.0 or google-auth
DEBUG:googleapiclient.discovery:URL being requested: GET https://www.googleapis.com/discovery/v1/apis/gmail/v1/rest
INFO:root:connected to Gmail API
DEBUG:googleapiclient.discovery:URL being requested: GET https://gmail.googleapis.com/gmail/v1/users/me/messages?labelIds=INBOX&alt=json
DEBUG:googleapiclient.discovery:URL being requested: GET https://gmail.googleapis.com/gmail/v1/users/me/messages/17589ab2ce4e1fc4?alt=json
DEBUG:googleapiclient.discovery:URL being requested: GET https://gmail.googleapis.com/gmail/v1/users/me/messages/17589601e24d1b0a?alt=json
DEBUG:googleapiclient.discovery:URL being requested: GET https://gmail.googleapis.com/gmail/v1/users/me/messages/17589488cedc2852?alt=json
DEBUG:googleapiclient.discovery:URL being requested: GET https://gmail.googleapis.com/gmail/v1/users/me/messages/175894336dfcbb46?alt=json
DEBUG:urllib3.connectionpool:Starting new HTTPS connection (1): webhook.site:443
DEBUG:urllib3.connectionpool:https://webhook.site:443 "POST /?message=location HTTP/1.1" 405 None
WARNING:googleapiclient.discovery_cache:file_cache is unavailable when using oauth2client >= 4.0.0 or google-auth
Traceback (most recent call last):
  File "C:\Users\sshho\anaconda3\envs\GmailAPI\lib\site-packages\googleapiclient\discovery_cache\file_cache.py", line 33, in <module>
    from oauth2client.contrib.locked_file import LockedFile
ModuleNotFoundError: No module named 'oauth2client'

During handling of the above exception, another exception occurred:

Traceback (most recent call last):
  File "C:\Users\sshho\anaconda3\envs\GmailAPI\lib\site-packages\googleapiclient\discovery_cache\file_cache.py", line 37, in <module>
    from oauth2client.locked_file import LockedFile
ModuleNotFoundError: No module named 'oauth2client'

During handling of the above exception, another exception occurred:

Traceback (most recent call last):
  File "C:\Users\sshho\anaconda3\envs\GmailAPI\lib\site-packages\googleapiclient\discovery_cache\__init__.py", line 44, in autodetect
    from . import file_cache
  File "C:\Users\sshho\anaconda3\envs\GmailAPI\lib\site-packages\googleapiclient\discovery_cache\file_cache.py", line 40, in <module>
    raise ImportError(
ImportError: file_cache is unavailable when using oauth2client >= 4.0.0 or google-auth
DEBUG:googleapiclient.discovery:URL being requested: GET https://www.googleapis.com/discovery/v1/apis/gmail/v1/rest
INFO:root:connected to Gmail API
DEBUG:googleapiclient.discovery:URL being requested: GET https://gmail.googleapis.com/gmail/v1/users/me/messages?labelIds=INBOX&alt=json
DEBUG:googleapiclient.discovery:URL being requested: GET https://gmail.googleapis.com/gmail/v1/users/me/messages/17589ab2ce4e1fc4?alt=json
DEBUG:googleapiclient.discovery:URL being requested: GET https://gmail.googleapis.com/gmail/v1/users/me/messages/17589601e24d1b0a?alt=json
DEBUG:googleapiclient.discovery:URL being requested: GET https://gmail.googleapis.com/gmail/v1/users/me/messages/17589488cedc2852?alt=json
DEBUG:googleapiclient.discovery:URL being requested: GET https://gmail.googleapis.com/gmail/v1/users/me/messages/175894336dfcbb46?alt=json
WARNING:googleapiclient.discovery_cache:file_cache is unavailable when using oauth2client >= 4.0.0 or google-auth
Traceback (most recent call last):
  File "C:\Users\sshho\anaconda3\envs\GmailAPI\lib\site-packages\googleapiclient\discovery_cache\file_cache.py", line 33, in <module>
    from oauth2client.contrib.locked_file import LockedFile
ModuleNotFoundError: No module named 'oauth2client'

During handling of the above exception, another exception occurred:

Traceback (most recent call last):
  File "C:\Users\sshho\anaconda3\envs\GmailAPI\lib\site-packages\googleapiclient\discovery_cache\file_cache.py", line 37, in <module>
    from oauth2client.locked_file import LockedFile
ModuleNotFoundError: No module named 'oauth2client'

During handling of the above exception, another exception occurred:

Traceback (most recent call last):
  File "C:\Users\sshho\anaconda3\envs\GmailAPI\lib\site-packages\googleapiclient\discovery_cache\__init__.py", line 44, in autodetect
    from . import file_cache
  File "C:\Users\sshho\anaconda3\envs\GmailAPI\lib\site-packages\googleapiclient\discovery_cache\file_cache.py", line 40, in <module>
    raise ImportError(
ImportError: file_cache is unavailable when using oauth2client >= 4.0.0 or google-auth
DEBUG:googleapiclient.discovery:URL being requested: GET https://www.googleapis.com/discovery/v1/apis/gmail/v1/rest
INFO:root:connected to Gmail API
DEBUG:urllib3.connectionpool:Starting new HTTPS connection (1): webhook.site:443
DEBUG:urllib3.connectionpool:https://webhook.site:443 "POST /?message=location HTTP/1.1" 405 None
WARNING:googleapiclient.discovery_cache:file_cache is unavailable when using oauth2client >= 4.0.0 or google-auth
Traceback (most recent call last):
  File "C:\Users\sshho\anaconda3\envs\GmailAPI\lib\site-packages\googleapiclient\discovery_cache\file_cache.py", line 33, in <module>
    from oauth2client.contrib.locked_file import LockedFile
ModuleNotFoundError: No module named 'oauth2client'

During handling of the above exception, another exception occurred:

Traceback (most recent call last):
  File "C:\Users\sshho\anaconda3\envs\GmailAPI\lib\site-packages\googleapiclient\discovery_cache\file_cache.py", line 37, in <module>
    from oauth2client.locked_file import LockedFile
ModuleNotFoundError: No module named 'oauth2client'

During handling of the above exception, another exception occurred:

Traceback (most recent call last):
  File "C:\Users\sshho\anaconda3\envs\GmailAPI\lib\site-packages\googleapiclient\discovery_cache\__init__.py", line 44, in autodetect
    from . import file_cache
  File "C:\Users\sshho\anaconda3\envs\GmailAPI\lib\site-packages\googleapiclient\discovery_cache\file_cache.py", line 40, in <module>
    raise ImportError(
ImportError: file_cache is unavailable when using oauth2client >= 4.0.0 or google-auth
DEBUG:googleapiclient.discovery:URL being requested: GET https://www.googleapis.com/discovery/v1/apis/gmail/v1/rest
INFO:root:connected to Gmail API
DEBUG:urllib3.connectionpool:Starting new HTTPS connection (1): webhook.site:443
DEBUG:urllib3.connectionpool:https://webhook.site:443 "POST /38703b0d-ba51-49b8-9e8a-f9aaa82c4152?message=location HTTP/1.1" 200 None
WARNING:googleapiclient.discovery_cache:file_cache is unavailable when using oauth2client >= 4.0.0 or google-auth
Traceback (most recent call last):
  File "C:\Users\sshho\anaconda3\envs\GmailAPI\lib\site-packages\googleapiclient\discovery_cache\file_cache.py", line 33, in <module>
    from oauth2client.contrib.locked_file import LockedFile
ModuleNotFoundError: No module named 'oauth2client'

During handling of the above exception, another exception occurred:

Traceback (most recent call last):
  File "C:\Users\sshho\anaconda3\envs\GmailAPI\lib\site-packages\googleapiclient\discovery_cache\file_cache.py", line 37, in <module>
    from oauth2client.locked_file import LockedFile
ModuleNotFoundError: No module named 'oauth2client'

During handling of the above exception, another exception occurred:

Traceback (most recent call last):
  File "C:\Users\sshho\anaconda3\envs\GmailAPI\lib\site-packages\googleapiclient\discovery_cache\__init__.py", line 44, in autodetect
    from . import file_cache
  File "C:\Users\sshho\anaconda3\envs\GmailAPI\lib\site-packages\googleapiclient\discovery_cache\file_cache.py", line 40, in <module>
    raise ImportError(
ImportError: file_cache is unavailable when using oauth2client >= 4.0.0 or google-auth
DEBUG:googleapiclient.discovery:URL being requested: GET https://www.googleapis.com/discovery/v1/apis/gmail/v1/rest
INFO:root:connected to Gmail API
DEBUG:urllib3.connectionpool:Starting new HTTPS connection (1): webhook.site:443
WARNING:googleapiclient.discovery_cache:file_cache is unavailable when using oauth2client >= 4.0.0 or google-auth
Traceback (most recent call last):
  File "C:\Users\sshho\anaconda3\envs\GmailAPI\lib\site-packages\googleapiclient\discovery_cache\file_cache.py", line 33, in <module>
    from oauth2client.contrib.locked_file import LockedFile
ModuleNotFoundError: No module named 'oauth2client'

During handling of the above exception, another exception occurred:

Traceback (most recent call last):
  File "C:\Users\sshho\anaconda3\envs\GmailAPI\lib\site-packages\googleapiclient\discovery_cache\file_cache.py", line 37, in <module>
    from oauth2client.locked_file import LockedFile
ModuleNotFoundError: No module named 'oauth2client'

During handling of the above exception, another exception occurred:

Traceback (most recent call last):
  File "C:\Users\sshho\anaconda3\envs\GmailAPI\lib\site-packages\googleapiclient\discovery_cache\__init__.py", line 44, in autodetect
    from . import file_cache
  File "C:\Users\sshho\anaconda3\envs\GmailAPI\lib\site-packages\googleapiclient\discovery_cache\file_cache.py", line 40, in <module>
    raise ImportError(
ImportError: file_cache is unavailable when using oauth2client >= 4.0.0 or google-auth
DEBUG:googleapiclient.discovery:URL being requested: GET https://www.googleapis.com/discovery/v1/apis/gmail/v1/rest
INFO:root:connected to Gmail API
DEBUG:urllib3.connectionpool:Starting new HTTPS connection (1): webhook.site:443
DEBUG:urllib3.connectionpool:https://webhook.site:443 "POST /38703b0d-ba51-49b8-9e8a-f9aaa82c4152 HTTP/1.1" 200 None
WARNING:googleapiclient.discovery_cache:file_cache is unavailable when using oauth2client >= 4.0.0 or google-auth
Traceback (most recent call last):
  File "C:\Users\sshho\anaconda3\envs\GmailAPI\lib\site-packages\googleapiclient\discovery_cache\file_cache.py", line 33, in <module>
    from oauth2client.contrib.locked_file import LockedFile
ModuleNotFoundError: No module named 'oauth2client'

During handling of the above exception, another exception occurred:

Traceback (most recent call last):
  File "C:\Users\sshho\anaconda3\envs\GmailAPI\lib\site-packages\googleapiclient\discovery_cache\file_cache.py", line 37, in <module>
    from oauth2client.locked_file import LockedFile
ModuleNotFoundError: No module named 'oauth2client'

During handling of the above exception, another exception occurred:

Traceback (most recent call last):
  File "C:\Users\sshho\anaconda3\envs\GmailAPI\lib\site-packages\googleapiclient\discovery_cache\__init__.py", line 44, in autodetect
    from . import file_cache
  File "C:\Users\sshho\anaconda3\envs\GmailAPI\lib\site-packages\googleapiclient\discovery_cache\file_cache.py", line 40, in <module>
    raise ImportError(
ImportError: file_cache is unavailable when using oauth2client >= 4.0.0 or google-auth
DEBUG:googleapiclient.discovery:URL being requested: GET https://www.googleapis.com/discovery/v1/apis/gmail/v1/rest
INFO:root:connected to Gmail API
DEBUG:urllib3.connectionpool:Starting new HTTPS connection (1): webhook.site:443
DEBUG:urllib3.connectionpool:https://webhook.site:443 "POST /38703b0d-ba51-49b8-9e8a-f9aaa82c4152 HTTP/1.1" 200 None
WARNING:googleapiclient.discovery_cache:file_cache is unavailable when using oauth2client >= 4.0.0 or google-auth
Traceback (most recent call last):
  File "C:\Users\sshho\anaconda3\envs\GmailAPI\lib\site-packages\googleapiclient\discovery_cache\file_cache.py", line 33, in <module>
    from oauth2client.contrib.locked_file import LockedFile
ModuleNotFoundError: No module named 'oauth2client'

During handling of the above exception, another exception occurred:

Traceback (most recent call last):
  File "C:\Users\sshho\anaconda3\envs\GmailAPI\lib\site-packages\googleapiclient\discovery_cache\file_cache.py", line 37, in <module>
    from oauth2client.locked_file import LockedFile
ModuleNotFoundError: No module named 'oauth2client'

During handling of the above exception, another exception occurred:

Traceback (most recent call last):
  File "C:\Users\sshho\anaconda3\envs\GmailAPI\lib\site-packages\googleapiclient\discovery_cache\__init__.py", line 44, in autodetect
    from . import file_cache
  File "C:\Users\sshho\anaconda3\envs\GmailAPI\lib\site-packages\googleapiclient\discovery_cache\file_cache.py", line 40, in <module>
    raise ImportError(
ImportError: file_cache is unavailable when using oauth2client >= 4.0.0 or google-auth
DEBUG:googleapiclient.discovery:URL being requested: GET https://www.googleapis.com/discovery/v1/apis/gmail/v1/rest
INFO:root:connected to Gmail API
DEBUG:googleapiclient.discovery:URL being requested: GET https://gmail.googleapis.com/gmail/v1/users/me/messages?labelIds=INBOX&alt=json
DEBUG:googleapiclient.discovery:URL being requested: GET https://gmail.googleapis.com/gmail/v1/users/me/messages/17589ab2ce4e1fc4?alt=json
DEBUG:googleapiclient.discovery:URL being requested: GET https://gmail.googleapis.com/gmail/v1/users/me/messages/17589601e24d1b0a?alt=json
DEBUG:googleapiclient.discovery:URL being requested: GET https://gmail.googleapis.com/gmail/v1/users/me/messages/17589488cedc2852?alt=json
DEBUG:googleapiclient.discovery:URL being requested: GET https://gmail.googleapis.com/gmail/v1/users/me/messages/175894336dfcbb46?alt=json
DEBUG:urllib3.connectionpool:Starting new HTTPS connection (1): webhook.site:443
DEBUG:urllib3.connectionpool:https://webhook.site:443 "POST /38703b0d-ba51-49b8-9e8a-f9aaa82c4152 HTTP/1.1" 200 None
WARNING:googleapiclient.discovery_cache:file_cache is unavailable when using oauth2client >= 4.0.0 or google-auth
Traceback (most recent call last):
  File "C:\Users\sshho\anaconda3\envs\GmailAPI\lib\site-packages\googleapiclient\discovery_cache\file_cache.py", line 33, in <module>
    from oauth2client.contrib.locked_file import LockedFile
ModuleNotFoundError: No module named 'oauth2client'

During handling of the above exception, another exception occurred:

Traceback (most recent call last):
  File "C:\Users\sshho\anaconda3\envs\GmailAPI\lib\site-packages\googleapiclient\discovery_cache\file_cache.py", line 37, in <module>
    from oauth2client.locked_file import LockedFile
ModuleNotFoundError: No module named 'oauth2client'

During handling of the above exception, another exception occurred:

Traceback (most recent call last):
  File "C:\Users\sshho\anaconda3\envs\GmailAPI\lib\site-packages\googleapiclient\discovery_cache\__init__.py", line 44, in autodetect
    from . import file_cache
  File "C:\Users\sshho\anaconda3\envs\GmailAPI\lib\site-packages\googleapiclient\discovery_cache\file_cache.py", line 40, in <module>
    raise ImportError(
ImportError: file_cache is unavailable when using oauth2client >= 4.0.0 or google-auth
DEBUG:googleapiclient.discovery:URL being requested: GET https://www.googleapis.com/discovery/v1/apis/gmail/v1/rest
INFO:root:connected to Gmail API
DEBUG:googleapiclient.discovery:URL being requested: GET https://gmail.googleapis.com/gmail/v1/users/me/messages?labelIds=INBOX&alt=json
DEBUG:googleapiclient.discovery:URL being requested: GET https://gmail.googleapis.com/gmail/v1/users/me/messages/17589ab2ce4e1fc4?alt=json
DEBUG:googleapiclient.discovery:URL being requested: GET https://gmail.googleapis.com/gmail/v1/users/me/messages/17589601e24d1b0a?alt=json
DEBUG:googleapiclient.discovery:URL being requested: GET https://gmail.googleapis.com/gmail/v1/users/me/messages/17589488cedc2852?alt=json
DEBUG:googleapiclient.discovery:URL being requested: GET https://gmail.googleapis.com/gmail/v1/users/me/messages/175894336dfcbb46?alt=json
DEBUG:urllib3.connectionpool:Starting new HTTPS connection (1): webhook.site:443
DEBUG:urllib3.connectionpool:https://webhook.site:443 "POST /38703b0d-ba51-49b8-9e8a-f9aaa82c4152 HTTP/1.1" 200 None
WARNING:googleapiclient.discovery_cache:file_cache is unavailable when using oauth2client >= 4.0.0 or google-auth
Traceback (most recent call last):
  File "C:\Users\sshho\anaconda3\envs\GmailAPI\lib\site-packages\googleapiclient\discovery_cache\file_cache.py", line 33, in <module>
    from oauth2client.contrib.locked_file import LockedFile
ModuleNotFoundError: No module named 'oauth2client'

During handling of the above exception, another exception occurred:

Traceback (most recent call last):
  File "C:\Users\sshho\anaconda3\envs\GmailAPI\lib\site-packages\googleapiclient\discovery_cache\file_cache.py", line 37, in <module>
    from oauth2client.locked_file import LockedFile
ModuleNotFoundError: No module named 'oauth2client'

During handling of the above exception, another exception occurred:

Traceback (most recent call last):
  File "C:\Users\sshho\anaconda3\envs\GmailAPI\lib\site-packages\googleapiclient\discovery_cache\__init__.py", line 44, in autodetect
    from . import file_cache
  File "C:\Users\sshho\anaconda3\envs\GmailAPI\lib\site-packages\googleapiclient\discovery_cache\file_cache.py", line 40, in <module>
    raise ImportError(
ImportError: file_cache is unavailable when using oauth2client >= 4.0.0 or google-auth
DEBUG:googleapiclient.discovery:URL being requested: GET https://www.googleapis.com/discovery/v1/apis/gmail/v1/rest
INFO:root:connected to Gmail API
DEBUG:googleapiclient.discovery:URL being requested: GET https://gmail.googleapis.com/gmail/v1/users/me/messages?labelIds=INBOX&alt=json
DEBUG:googleapiclient.discovery:URL being requested: GET https://gmail.googleapis.com/gmail/v1/users/me/messages/17589ab2ce4e1fc4?alt=json
DEBUG:googleapiclient.discovery:URL being requested: GET https://gmail.googleapis.com/gmail/v1/users/me/messages/17589601e24d1b0a?alt=json
DEBUG:googleapiclient.discovery:URL being requested: GET https://gmail.googleapis.com/gmail/v1/users/me/messages/17589488cedc2852?alt=json
DEBUG:googleapiclient.discovery:URL being requested: GET https://gmail.googleapis.com/gmail/v1/users/me/messages/175894336dfcbb46?alt=json
DEBUG:urllib3.connectionpool:Starting new HTTPS connection (1): webhook.site:443
DEBUG:urllib3.connectionpool:https://webhook.site:443 "POST /38703b0d-ba51-49b8-9e8a-f9aaa82c4152 HTTP/1.1" 200 None
DEBUG:urllib3.connectionpool:Starting new HTTPS connection (1): webhook.site:443
DEBUG:urllib3.connectionpool:https://webhook.site:443 "POST /38703b0d-ba51-49b8-9e8a-f9aaa82c4152 HTTP/1.1" 200 None
DEBUG:urllib3.connectionpool:Starting new HTTPS connection (1): webhook.site:443
DEBUG:urllib3.connectionpool:https://webhook.site:443 "POST /38703b0d-ba51-49b8-9e8a-f9aaa82c4152 HTTP/1.1" 200 None
WARNING:googleapiclient.discovery_cache:file_cache is unavailable when using oauth2client >= 4.0.0 or google-auth
Traceback (most recent call last):
  File "C:\Users\sshho\anaconda3\envs\GmailAPI\lib\site-packages\googleapiclient\discovery_cache\file_cache.py", line 33, in <module>
    from oauth2client.contrib.locked_file import LockedFile
ModuleNotFoundError: No module named 'oauth2client'

During handling of the above exception, another exception occurred:

Traceback (most recent call last):
  File "C:\Users\sshho\anaconda3\envs\GmailAPI\lib\site-packages\googleapiclient\discovery_cache\file_cache.py", line 37, in <module>
    from oauth2client.locked_file import LockedFile
ModuleNotFoundError: No module named 'oauth2client'

During handling of the above exception, another exception occurred:

Traceback (most recent call last):
  File "C:\Users\sshho\anaconda3\envs\GmailAPI\lib\site-packages\googleapiclient\discovery_cache\__init__.py", line 44, in autodetect
    from . import file_cache
  File "C:\Users\sshho\anaconda3\envs\GmailAPI\lib\site-packages\googleapiclient\discovery_cache\file_cache.py", line 40, in <module>
    raise ImportError(
ImportError: file_cache is unavailable when using oauth2client >= 4.0.0 or google-auth
DEBUG:googleapiclient.discovery:URL being requested: GET https://www.googleapis.com/discovery/v1/apis/gmail/v1/rest
INFO:root:connected to Gmail API
DEBUG:googleapiclient.discovery:URL being requested: GET https://gmail.googleapis.com/gmail/v1/users/me/messages?labelIds=INBOX&alt=json
DEBUG:googleapiclient.discovery:URL being requested: GET https://gmail.googleapis.com/gmail/v1/users/me/messages/17589ab2ce4e1fc4?alt=json
DEBUG:googleapiclient.discovery:URL being requested: GET https://gmail.googleapis.com/gmail/v1/users/me/messages/17589601e24d1b0a?alt=json
DEBUG:googleapiclient.discovery:URL being requested: GET https://gmail.googleapis.com/gmail/v1/users/me/messages/17589488cedc2852?alt=json
DEBUG:googleapiclient.discovery:URL being requested: GET https://gmail.googleapis.com/gmail/v1/users/me/messages/175894336dfcbb46?alt=json
DEBUG:google.auth.transport.requests:Making request: POST https://oauth2.googleapis.com/token
DEBUG:urllib3.connectionpool:Starting new HTTPS connection (1): oauth2.googleapis.com:443
DEBUG:urllib3.connectionpool:https://oauth2.googleapis.com:443 "POST /token HTTP/1.1" 200 None
WARNING:googleapiclient.discovery_cache:file_cache is unavailable when using oauth2client >= 4.0.0 or google-auth
Traceback (most recent call last):
  File "C:\Users\sshho\anaconda3\envs\GmailAPI\lib\site-packages\googleapiclient\discovery_cache\file_cache.py", line 33, in <module>
    from oauth2client.contrib.locked_file import LockedFile
ModuleNotFoundError: No module named 'oauth2client'

During handling of the above exception, another exception occurred:

Traceback (most recent call last):
  File "C:\Users\sshho\anaconda3\envs\GmailAPI\lib\site-packages\googleapiclient\discovery_cache\file_cache.py", line 37, in <module>
    from oauth2client.locked_file import LockedFile
ModuleNotFoundError: No module named 'oauth2client'

During handling of the above exception, another exception occurred:

Traceback (most recent call last):
  File "C:\Users\sshho\anaconda3\envs\GmailAPI\lib\site-packages\googleapiclient\discovery_cache\__init__.py", line 44, in autodetect
    from . import file_cache
  File "C:\Users\sshho\anaconda3\envs\GmailAPI\lib\site-packages\googleapiclient\discovery_cache\file_cache.py", line 40, in <module>
    raise ImportError(
ImportError: file_cache is unavailable when using oauth2client >= 4.0.0 or google-auth
DEBUG:googleapiclient.discovery:URL being requested: GET https://www.googleapis.com/discovery/v1/apis/gmail/v1/rest
INFO:root:connected to Gmail API
DEBUG:googleapiclient.discovery:URL being requested: GET https://gmail.googleapis.com/gmail/v1/users/me/messages?labelIds=INBOX&alt=json
DEBUG:googleapiclient.discovery:URL being requested: GET https://gmail.googleapis.com/gmail/v1/users/me/messages/17589ab2ce4e1fc4?alt=json
DEBUG:googleapiclient.discovery:URL being requested: GET https://gmail.googleapis.com/gmail/v1/users/me/messages/17589601e24d1b0a?alt=json
DEBUG:googleapiclient.discovery:URL being requested: GET https://gmail.googleapis.com/gmail/v1/users/me/messages/17589488cedc2852?alt=json
DEBUG:googleapiclient.discovery:URL being requested: GET https://gmail.googleapis.com/gmail/v1/users/me/messages/175894336dfcbb46?alt=json
DEBUG:urllib3.connectionpool:Starting new HTTPS connection (1): webhook.site:443
DEBUG:urllib3.connectionpool:https://webhook.site:443 "POST /38703b0d-ba51-49b8-9e8a-f9aaa82c4152 HTTP/1.1" 200 None
DEBUG:urllib3.connectionpool:Starting new HTTPS connection (1): webhook.site:443
DEBUG:urllib3.connectionpool:https://webhook.site:443 "POST /38703b0d-ba51-49b8-9e8a-f9aaa82c4152 HTTP/1.1" 200 None
DEBUG:urllib3.connectionpool:Starting new HTTPS connection (1): webhook.site:443
DEBUG:urllib3.connectionpool:https://webhook.site:443 "POST /38703b0d-ba51-49b8-9e8a-f9aaa82c4152 HTTP/1.1" 200 None
WARNING:googleapiclient.discovery_cache:file_cache is unavailable when using oauth2client >= 4.0.0 or google-auth
Traceback (most recent call last):
  File "C:\Users\sshho\anaconda3\envs\GmailAPI\lib\site-packages\googleapiclient\discovery_cache\file_cache.py", line 33, in <module>
    from oauth2client.contrib.locked_file import LockedFile
ModuleNotFoundError: No module named 'oauth2client'

During handling of the above exception, another exception occurred:

Traceback (most recent call last):
  File "C:\Users\sshho\anaconda3\envs\GmailAPI\lib\site-packages\googleapiclient\discovery_cache\file_cache.py", line 37, in <module>
    from oauth2client.locked_file import LockedFile
ModuleNotFoundError: No module named 'oauth2client'

During handling of the above exception, another exception occurred:

Traceback (most recent call last):
  File "C:\Users\sshho\anaconda3\envs\GmailAPI\lib\site-packages\googleapiclient\discovery_cache\__init__.py", line 44, in autodetect
    from . import file_cache
  File "C:\Users\sshho\anaconda3\envs\GmailAPI\lib\site-packages\googleapiclient\discovery_cache\file_cache.py", line 40, in <module>
    raise ImportError(
ImportError: file_cache is unavailable when using oauth2client >= 4.0.0 or google-auth
DEBUG:googleapiclient.discovery:URL being requested: GET https://www.googleapis.com/discovery/v1/apis/gmail/v1/rest
INFO:root:connected to Gmail API
DEBUG:googleapiclient.discovery:URL being requested: GET https://gmail.googleapis.com/gmail/v1/users/me/messages?labelIds=INBOX&alt=json
DEBUG:googleapiclient.discovery:URL being requested: GET https://gmail.googleapis.com/gmail/v1/users/me/messages/17589ab2ce4e1fc4?alt=json
DEBUG:googleapiclient.discovery:URL being requested: GET https://gmail.googleapis.com/gmail/v1/users/me/messages/17589601e24d1b0a?alt=json
DEBUG:googleapiclient.discovery:URL being requested: GET https://gmail.googleapis.com/gmail/v1/users/me/messages/17589488cedc2852?alt=json
DEBUG:googleapiclient.discovery:URL being requested: GET https://gmail.googleapis.com/gmail/v1/users/me/messages/175894336dfcbb46?alt=json
DEBUG:urllib3.connectionpool:Starting new HTTPS connection (1): webhook.site:443
DEBUG:urllib3.connectionpool:https://webhook.site:443 "POST /38703b0d-ba51-49b8-9e8a-f9aaa82c4152 HTTP/1.1" 200 None
DEBUG:urllib3.connectionpool:Starting new HTTPS connection (1): webhook.site:443
DEBUG:urllib3.connectionpool:https://webhook.site:443 "POST /38703b0d-ba51-49b8-9e8a-f9aaa82c4152 HTTP/1.1" 200 None
DEBUG:urllib3.connectionpool:Starting new HTTPS connection (1): webhook.site:443
DEBUG:urllib3.connectionpool:https://webhook.site:443 "POST /38703b0d-ba51-49b8-9e8a-f9aaa82c4152 HTTP/1.1" 200 None
WARNING:googleapiclient.discovery_cache:file_cache is unavailable when using oauth2client >= 4.0.0 or google-auth
Traceback (most recent call last):
  File "C:\Users\sshho\anaconda3\envs\GmailAPI\lib\site-packages\googleapiclient\discovery_cache\file_cache.py", line 33, in <module>
    from oauth2client.contrib.locked_file import LockedFile
ModuleNotFoundError: No module named 'oauth2client'

During handling of the above exception, another exception occurred:

Traceback (most recent call last):
  File "C:\Users\sshho\anaconda3\envs\GmailAPI\lib\site-packages\googleapiclient\discovery_cache\file_cache.py", line 37, in <module>
    from oauth2client.locked_file import LockedFile
ModuleNotFoundError: No module named 'oauth2client'

During handling of the above exception, another exception occurred:

Traceback (most recent call last):
  File "C:\Users\sshho\anaconda3\envs\GmailAPI\lib\site-packages\googleapiclient\discovery_cache\__init__.py", line 44, in autodetect
    from . import file_cache
  File "C:\Users\sshho\anaconda3\envs\GmailAPI\lib\site-packages\googleapiclient\discovery_cache\file_cache.py", line 40, in <module>
    raise ImportError(
ImportError: file_cache is unavailable when using oauth2client >= 4.0.0 or google-auth
DEBUG:googleapiclient.discovery:URL being requested: GET https://www.googleapis.com/discovery/v1/apis/gmail/v1/rest
INFO:root:connected to Gmail API
DEBUG:googleapiclient.discovery:URL being requested: GET https://gmail.googleapis.com/gmail/v1/users/me/messages?labelIds=INBOX&alt=json
DEBUG:googleapiclient.discovery:URL being requested: GET https://gmail.googleapis.com/gmail/v1/users/me/messages/17589ab2ce4e1fc4?alt=json
DEBUG:googleapiclient.discovery:URL being requested: GET https://gmail.googleapis.com/gmail/v1/users/me/messages/17589601e24d1b0a?alt=json
DEBUG:googleapiclient.discovery:URL being requested: GET https://gmail.googleapis.com/gmail/v1/users/me/messages/17589488cedc2852?alt=json
DEBUG:googleapiclient.discovery:URL being requested: GET https://gmail.googleapis.com/gmail/v1/users/me/messages/175894336dfcbb46?alt=json
WARNING:googleapiclient.discovery_cache:file_cache is unavailable when using oauth2client >= 4.0.0 or google-auth
Traceback (most recent call last):
  File "C:\Users\sshho\anaconda3\envs\GmailAPI\lib\site-packages\googleapiclient\discovery_cache\file_cache.py", line 33, in <module>
    from oauth2client.contrib.locked_file import LockedFile
ModuleNotFoundError: No module named 'oauth2client'

During handling of the above exception, another exception occurred:

Traceback (most recent call last):
  File "C:\Users\sshho\anaconda3\envs\GmailAPI\lib\site-packages\googleapiclient\discovery_cache\file_cache.py", line 37, in <module>
    from oauth2client.locked_file import LockedFile
ModuleNotFoundError: No module named 'oauth2client'

During handling of the above exception, another exception occurred:

Traceback (most recent call last):
  File "C:\Users\sshho\anaconda3\envs\GmailAPI\lib\site-packages\googleapiclient\discovery_cache\__init__.py", line 44, in autodetect
    from . import file_cache
  File "C:\Users\sshho\anaconda3\envs\GmailAPI\lib\site-packages\googleapiclient\discovery_cache\file_cache.py", line 40, in <module>
    raise ImportError(
ImportError: file_cache is unavailable when using oauth2client >= 4.0.0 or google-auth
DEBUG:googleapiclient.discovery:URL being requested: GET https://www.googleapis.com/discovery/v1/apis/gmail/v1/rest
INFO:root:connected to Gmail API
DEBUG:googleapiclient.discovery:URL being requested: GET https://gmail.googleapis.com/gmail/v1/users/me/messages?labelIds=INBOX&alt=json
DEBUG:googleapiclient.discovery:URL being requested: GET https://gmail.googleapis.com/gmail/v1/users/me/messages/17589ab2ce4e1fc4?alt=json
DEBUG:googleapiclient.discovery:URL being requested: GET https://gmail.googleapis.com/gmail/v1/users/me/messages/17589601e24d1b0a?alt=json
DEBUG:googleapiclient.discovery:URL being requested: GET https://gmail.googleapis.com/gmail/v1/users/me/messages/17589488cedc2852?alt=json
DEBUG:googleapiclient.discovery:URL being requested: GET https://gmail.googleapis.com/gmail/v1/users/me/messages/175894336dfcbb46?alt=json
DEBUG:urllib3.connectionpool:Starting new HTTPS connection (1): webhook.site:443
DEBUG:urllib3.connectionpool:https://webhook.site:443 "POST /38703b0d-ba51-49b8-9e8a-f9aaa82c4152 HTTP/1.1" 200 None
DEBUG:urllib3.connectionpool:Starting new HTTPS connection (1): webhook.site:443
DEBUG:urllib3.connectionpool:https://webhook.site:443 "POST /38703b0d-ba51-49b8-9e8a-f9aaa82c4152 HTTP/1.1" 200 None
DEBUG:urllib3.connectionpool:Starting new HTTPS connection (1): webhook.site:443
DEBUG:urllib3.connectionpool:https://webhook.site:443 "POST /38703b0d-ba51-49b8-9e8a-f9aaa82c4152 HTTP/1.1" 200 None
WARNING:googleapiclient.discovery_cache:file_cache is unavailable when using oauth2client >= 4.0.0 or google-auth
Traceback (most recent call last):
  File "C:\Users\sshho\anaconda3\envs\GmailAPI\lib\site-packages\googleapiclient\discovery_cache\file_cache.py", line 33, in <module>
    from oauth2client.contrib.locked_file import LockedFile
ModuleNotFoundError: No module named 'oauth2client'

During handling of the above exception, another exception occurred:

Traceback (most recent call last):
  File "C:\Users\sshho\anaconda3\envs\GmailAPI\lib\site-packages\googleapiclient\discovery_cache\file_cache.py", line 37, in <module>
    from oauth2client.locked_file import LockedFile
ModuleNotFoundError: No module named 'oauth2client'

During handling of the above exception, another exception occurred:

Traceback (most recent call last):
  File "C:\Users\sshho\anaconda3\envs\GmailAPI\lib\site-packages\googleapiclient\discovery_cache\__init__.py", line 44, in autodetect
    from . import file_cache
  File "C:\Users\sshho\anaconda3\envs\GmailAPI\lib\site-packages\googleapiclient\discovery_cache\file_cache.py", line 40, in <module>
    raise ImportError(
ImportError: file_cache is unavailable when using oauth2client >= 4.0.0 or google-auth
DEBUG:googleapiclient.discovery:URL being requested: GET https://www.googleapis.com/discovery/v1/apis/gmail/v1/rest
INFO:root:connected to Gmail API
DEBUG:googleapiclient.discovery:URL being requested: GET https://gmail.googleapis.com/gmail/v1/users/me/messages?labelIds=INBOX&alt=json
DEBUG:googleapiclient.discovery:URL being requested: GET https://gmail.googleapis.com/gmail/v1/users/me/messages/17589ab2ce4e1fc4?alt=json
DEBUG:googleapiclient.discovery:URL being requested: GET https://gmail.googleapis.com/gmail/v1/users/me/messages/17589601e24d1b0a?alt=json
DEBUG:googleapiclient.discovery:URL being requested: GET https://gmail.googleapis.com/gmail/v1/users/me/messages/17589488cedc2852?alt=json
DEBUG:googleapiclient.discovery:URL being requested: GET https://gmail.googleapis.com/gmail/v1/users/me/messages/175894336dfcbb46?alt=json
WARNING:googleapiclient.discovery_cache:file_cache is unavailable when using oauth2client >= 4.0.0 or google-auth
Traceback (most recent call last):
  File "C:\Users\sshho\anaconda3\envs\GmailAPI\lib\site-packages\googleapiclient\discovery_cache\file_cache.py", line 33, in <module>
    from oauth2client.contrib.locked_file import LockedFile
ModuleNotFoundError: No module named 'oauth2client'

During handling of the above exception, another exception occurred:

Traceback (most recent call last):
  File "C:\Users\sshho\anaconda3\envs\GmailAPI\lib\site-packages\googleapiclient\discovery_cache\file_cache.py", line 37, in <module>
    from oauth2client.locked_file import LockedFile
ModuleNotFoundError: No module named 'oauth2client'

During handling of the above exception, another exception occurred:

Traceback (most recent call last):
  File "C:\Users\sshho\anaconda3\envs\GmailAPI\lib\site-packages\googleapiclient\discovery_cache\__init__.py", line 44, in autodetect
    from . import file_cache
  File "C:\Users\sshho\anaconda3\envs\GmailAPI\lib\site-packages\googleapiclient\discovery_cache\file_cache.py", line 40, in <module>
    raise ImportError(
ImportError: file_cache is unavailable when using oauth2client >= 4.0.0 or google-auth
DEBUG:googleapiclient.discovery:URL being requested: GET https://www.googleapis.com/discovery/v1/apis/gmail/v1/rest
INFO:root:connected to Gmail API
DEBUG:googleapiclient.discovery:URL being requested: GET https://gmail.googleapis.com/gmail/v1/users/me/messages?labelIds=INBOX&alt=json
DEBUG:googleapiclient.discovery:URL being requested: GET https://gmail.googleapis.com/gmail/v1/users/me/messages/17589ab2ce4e1fc4?alt=json
DEBUG:googleapiclient.discovery:URL being requested: GET https://gmail.googleapis.com/gmail/v1/users/me/messages/17589601e24d1b0a?alt=json
DEBUG:googleapiclient.discovery:URL being requested: GET https://gmail.googleapis.com/gmail/v1/users/me/messages/17589488cedc2852?alt=json
DEBUG:googleapiclient.discovery:URL being requested: GET https://gmail.googleapis.com/gmail/v1/users/me/messages/175894336dfcbb46?alt=json
DEBUG:urllib3.connectionpool:Starting new HTTPS connection (1): webhook.site:443
DEBUG:urllib3.connectionpool:https://webhook.site:443 "POST /38703b0d-ba51-49b8-9e8a-f9aaa82c4152 HTTP/1.1" 200 None
DEBUG:urllib3.connectionpool:Starting new HTTPS connection (1): webhook.site:443
DEBUG:urllib3.connectionpool:https://webhook.site:443 "POST /38703b0d-ba51-49b8-9e8a-f9aaa82c4152 HTTP/1.1" 200 None
DEBUG:urllib3.connectionpool:Starting new HTTPS connection (1): webhook.site:443
DEBUG:urllib3.connectionpool:https://webhook.site:443 "POST /38703b0d-ba51-49b8-9e8a-f9aaa82c4152 HTTP/1.1" 200 None
WARNING:googleapiclient.discovery_cache:file_cache is unavailable when using oauth2client >= 4.0.0 or google-auth
Traceback (most recent call last):
  File "C:\Users\sshho\anaconda3\envs\GmailAPI\lib\site-packages\googleapiclient\discovery_cache\file_cache.py", line 33, in <module>
    from oauth2client.contrib.locked_file import LockedFile
ModuleNotFoundError: No module named 'oauth2client'

During handling of the above exception, another exception occurred:

Traceback (most recent call last):
  File "C:\Users\sshho\anaconda3\envs\GmailAPI\lib\site-packages\googleapiclient\discovery_cache\file_cache.py", line 37, in <module>
    from oauth2client.locked_file import LockedFile
ModuleNotFoundError: No module named 'oauth2client'

During handling of the above exception, another exception occurred:

Traceback (most recent call last):
  File "C:\Users\sshho\anaconda3\envs\GmailAPI\lib\site-packages\googleapiclient\discovery_cache\__init__.py", line 44, in autodetect
    from . import file_cache
  File "C:\Users\sshho\anaconda3\envs\GmailAPI\lib\site-packages\googleapiclient\discovery_cache\file_cache.py", line 40, in <module>
    raise ImportError(
ImportError: file_cache is unavailable when using oauth2client >= 4.0.0 or google-auth
DEBUG:googleapiclient.discovery:URL being requested: GET https://www.googleapis.com/discovery/v1/apis/gmail/v1/rest
INFO:root:connected to Gmail API
DEBUG:googleapiclient.discovery:URL being requested: GET https://gmail.googleapis.com/gmail/v1/users/me/messages?labelIds=INBOX&alt=json
DEBUG:googleapiclient.discovery:URL being requested: GET https://gmail.googleapis.com/gmail/v1/users/me/messages/17589ab2ce4e1fc4?alt=json
DEBUG:googleapiclient.discovery:URL being requested: GET https://gmail.googleapis.com/gmail/v1/users/me/messages/17589601e24d1b0a?alt=json
DEBUG:googleapiclient.discovery:URL being requested: GET https://gmail.googleapis.com/gmail/v1/users/me/messages/17589488cedc2852?alt=json
DEBUG:googleapiclient.discovery:URL being requested: GET https://gmail.googleapis.com/gmail/v1/users/me/messages/175894336dfcbb46?alt=json
DEBUG:urllib3.connectionpool:Starting new HTTPS connection (1): webhook.site:443
DEBUG:urllib3.connectionpool:https://webhook.site:443 "POST /38703b0d-ba51-49b8-9e8a-f9aaa82c4152 HTTP/1.1" 200 None
WARNING:googleapiclient.discovery_cache:file_cache is unavailable when using oauth2client >= 4.0.0 or google-auth
Traceback (most recent call last):
  File "C:\Users\sshho\anaconda3\envs\GmailAPI\lib\site-packages\googleapiclient\discovery_cache\file_cache.py", line 33, in <module>
    from oauth2client.contrib.locked_file import LockedFile
ModuleNotFoundError: No module named 'oauth2client'

During handling of the above exception, another exception occurred:

Traceback (most recent call last):
  File "C:\Users\sshho\anaconda3\envs\GmailAPI\lib\site-packages\googleapiclient\discovery_cache\file_cache.py", line 37, in <module>
    from oauth2client.locked_file import LockedFile
ModuleNotFoundError: No module named 'oauth2client'

During handling of the above exception, another exception occurred:

Traceback (most recent call last):
  File "C:\Users\sshho\anaconda3\envs\GmailAPI\lib\site-packages\googleapiclient\discovery_cache\__init__.py", line 44, in autodetect
    from . import file_cache
  File "C:\Users\sshho\anaconda3\envs\GmailAPI\lib\site-packages\googleapiclient\discovery_cache\file_cache.py", line 40, in <module>
    raise ImportError(
ImportError: file_cache is unavailable when using oauth2client >= 4.0.0 or google-auth
DEBUG:googleapiclient.discovery:URL being requested: GET https://www.googleapis.com/discovery/v1/apis/gmail/v1/rest
INFO:root:connected to Gmail API
DEBUG:googleapiclient.discovery:URL being requested: GET https://gmail.googleapis.com/gmail/v1/users/me/messages?labelIds=INBOX&alt=json
DEBUG:googleapiclient.discovery:URL being requested: GET https://gmail.googleapis.com/gmail/v1/users/me/messages/17589ab2ce4e1fc4?alt=json
DEBUG:googleapiclient.discovery:URL being requested: GET https://gmail.googleapis.com/gmail/v1/users/me/messages/17589601e24d1b0a?alt=json
DEBUG:googleapiclient.discovery:URL being requested: GET https://gmail.googleapis.com/gmail/v1/users/me/messages/17589488cedc2852?alt=json
DEBUG:googleapiclient.discovery:URL being requested: GET https://gmail.googleapis.com/gmail/v1/users/me/messages/175894336dfcbb46?alt=json
DEBUG:urllib3.connectionpool:Starting new HTTPS connection (1): webhook.site:443
DEBUG:urllib3.connectionpool:https://webhook.site:443 "POST /38703b0d-ba51-49b8-9e8a-f9aaa82c4152 HTTP/1.1" 200 None
DEBUG:googleapiclient.discovery:URL being requested: GET https://gmail.googleapis.com/gmail/v1/users/me/messages?labelIds=INBOX&alt=json
DEBUG:googleapiclient.discovery:URL being requested: GET https://gmail.googleapis.com/gmail/v1/users/me/messages/17589ab2ce4e1fc4?alt=json
DEBUG:googleapiclient.discovery:URL being requested: GET https://gmail.googleapis.com/gmail/v1/users/me/messages/17589601e24d1b0a?alt=json
DEBUG:googleapiclient.discovery:URL being requested: GET https://gmail.googleapis.com/gmail/v1/users/me/messages/17589488cedc2852?alt=json
DEBUG:googleapiclient.discovery:URL being requested: GET https://gmail.googleapis.com/gmail/v1/users/me/messages/175894336dfcbb46?alt=json
DEBUG:urllib3.connectionpool:Starting new HTTPS connection (1): webhook.site:443
DEBUG:urllib3.connectionpool:https://webhook.site:443 "POST /38703b0d-ba51-49b8-9e8a-f9aaa82c4152 HTTP/1.1" 200 None
DEBUG:googleapiclient.discovery:URL being requested: GET https://gmail.googleapis.com/gmail/v1/users/me/messages?labelIds=INBOX&alt=json
DEBUG:googleapiclient.discovery:URL being requested: GET https://gmail.googleapis.com/gmail/v1/users/me/messages/17589ab2ce4e1fc4?alt=json
DEBUG:googleapiclient.discovery:URL being requested: GET https://gmail.googleapis.com/gmail/v1/users/me/messages/17589601e24d1b0a?alt=json
DEBUG:googleapiclient.discovery:URL being requested: GET https://gmail.googleapis.com/gmail/v1/users/me/messages/17589488cedc2852?alt=json
DEBUG:googleapiclient.discovery:URL being requested: GET https://gmail.googleapis.com/gmail/v1/users/me/messages/175894336dfcbb46?alt=json
DEBUG:urllib3.connectionpool:Starting new HTTPS connection (1): webhook.site:443
DEBUG:urllib3.connectionpool:https://webhook.site:443 "POST /38703b0d-ba51-49b8-9e8a-f9aaa82c4152 HTTP/1.1" 200 None
DEBUG:googleapiclient.discovery:URL being requested: GET https://gmail.googleapis.com/gmail/v1/users/me/messages?labelIds=INBOX&alt=json
DEBUG:googleapiclient.discovery:URL being requested: GET https://gmail.googleapis.com/gmail/v1/users/me/messages/17589ab2ce4e1fc4?alt=json
DEBUG:googleapiclient.discovery:URL being requested: GET https://gmail.googleapis.com/gmail/v1/users/me/messages/17589601e24d1b0a?alt=json
DEBUG:googleapiclient.discovery:URL being requested: GET https://gmail.googleapis.com/gmail/v1/users/me/messages/17589488cedc2852?alt=json
DEBUG:googleapiclient.discovery:URL being requested: GET https://gmail.googleapis.com/gmail/v1/users/me/messages/175894336dfcbb46?alt=json
DEBUG:urllib3.connectionpool:Starting new HTTPS connection (1): webhook.site:443
DEBUG:urllib3.connectionpool:https://webhook.site:443 "POST /38703b0d-ba51-49b8-9e8a-f9aaa82c4152 HTTP/1.1" 200 None
DEBUG:googleapiclient.discovery:URL being requested: GET https://gmail.googleapis.com/gmail/v1/users/me/messages?labelIds=INBOX&alt=json
DEBUG:googleapiclient.discovery:URL being requested: GET https://gmail.googleapis.com/gmail/v1/users/me/messages/17589ab2ce4e1fc4?alt=json
DEBUG:googleapiclient.discovery:URL being requested: GET https://gmail.googleapis.com/gmail/v1/users/me/messages/17589601e24d1b0a?alt=json
DEBUG:googleapiclient.discovery:URL being requested: GET https://gmail.googleapis.com/gmail/v1/users/me/messages/17589488cedc2852?alt=json
DEBUG:googleapiclient.discovery:URL being requested: GET https://gmail.googleapis.com/gmail/v1/users/me/messages/175894336dfcbb46?alt=json
DEBUG:urllib3.connectionpool:Starting new HTTPS connection (1): webhook.site:443
DEBUG:urllib3.connectionpool:https://webhook.site:443 "POST /38703b0d-ba51-49b8-9e8a-f9aaa82c4152 HTTP/1.1" 200 None
DEBUG:googleapiclient.discovery:URL being requested: GET https://gmail.googleapis.com/gmail/v1/users/me/messages?labelIds=INBOX&alt=json
DEBUG:googleapiclient.discovery:URL being requested: GET https://gmail.googleapis.com/gmail/v1/users/me/messages/17589ab2ce4e1fc4?alt=json
DEBUG:googleapiclient.discovery:URL being requested: GET https://gmail.googleapis.com/gmail/v1/users/me/messages/17589601e24d1b0a?alt=json
DEBUG:googleapiclient.discovery:URL being requested: GET https://gmail.googleapis.com/gmail/v1/users/me/messages/17589488cedc2852?alt=json
DEBUG:googleapiclient.discovery:URL being requested: GET https://gmail.googleapis.com/gmail/v1/users/me/messages/175894336dfcbb46?alt=json
DEBUG:urllib3.connectionpool:Starting new HTTPS connection (1): webhook.site:443
DEBUG:urllib3.connectionpool:https://webhook.site:443 "POST /38703b0d-ba51-49b8-9e8a-f9aaa82c4152 HTTP/1.1" 200 None
DEBUG:googleapiclient.discovery:URL being requested: GET https://gmail.googleapis.com/gmail/v1/users/me/messages?labelIds=INBOX&alt=json
DEBUG:googleapiclient.discovery:URL being requested: GET https://gmail.googleapis.com/gmail/v1/users/me/messages/17589ab2ce4e1fc4?alt=json
DEBUG:googleapiclient.discovery:URL being requested: GET https://gmail.googleapis.com/gmail/v1/users/me/messages/17589601e24d1b0a?alt=json
DEBUG:googleapiclient.discovery:URL being requested: GET https://gmail.googleapis.com/gmail/v1/users/me/messages/17589488cedc2852?alt=json
DEBUG:googleapiclient.discovery:URL being requested: GET https://gmail.googleapis.com/gmail/v1/users/me/messages/175894336dfcbb46?alt=json
DEBUG:urllib3.connectionpool:Starting new HTTPS connection (1): webhook.site:443
DEBUG:urllib3.connectionpool:https://webhook.site:443 "POST /38703b0d-ba51-49b8-9e8a-f9aaa82c4152 HTTP/1.1" 200 None
WARNING:googleapiclient.discovery_cache:file_cache is unavailable when using oauth2client >= 4.0.0 or google-auth
Traceback (most recent call last):
  File "C:\Users\sshho\anaconda3\envs\GmailAPI\lib\site-packages\googleapiclient\discovery_cache\file_cache.py", line 33, in <module>
    from oauth2client.contrib.locked_file import LockedFile
ModuleNotFoundError: No module named 'oauth2client'

During handling of the above exception, another exception occurred:

Traceback (most recent call last):
  File "C:\Users\sshho\anaconda3\envs\GmailAPI\lib\site-packages\googleapiclient\discovery_cache\file_cache.py", line 37, in <module>
    from oauth2client.locked_file import LockedFile
ModuleNotFoundError: No module named 'oauth2client'

During handling of the above exception, another exception occurred:

Traceback (most recent call last):
  File "C:\Users\sshho\anaconda3\envs\GmailAPI\lib\site-packages\googleapiclient\discovery_cache\__init__.py", line 44, in autodetect
    from . import file_cache
  File "C:\Users\sshho\anaconda3\envs\GmailAPI\lib\site-packages\googleapiclient\discovery_cache\file_cache.py", line 40, in <module>
    raise ImportError(
ImportError: file_cache is unavailable when using oauth2client >= 4.0.0 or google-auth
DEBUG:googleapiclient.discovery:URL being requested: GET https://www.googleapis.com/discovery/v1/apis/gmail/v1/rest
INFO:root:connected to Gmail API
DEBUG:googleapiclient.discovery:URL being requested: GET https://gmail.googleapis.com/gmail/v1/users/me/messages?labelIds=INBOX&alt=json
DEBUG:googleapiclient.discovery:URL being requested: GET https://gmail.googleapis.com/gmail/v1/users/me/messages/17589ab2ce4e1fc4?alt=json
DEBUG:googleapiclient.discovery:URL being requested: GET https://gmail.googleapis.com/gmail/v1/users/me/messages/17589601e24d1b0a?alt=json
DEBUG:googleapiclient.discovery:URL being requested: GET https://gmail.googleapis.com/gmail/v1/users/me/messages/17589488cedc2852?alt=json
DEBUG:googleapiclient.discovery:URL being requested: GET https://gmail.googleapis.com/gmail/v1/users/me/messages/175894336dfcbb46?alt=json
DEBUG:urllib3.connectionpool:Starting new HTTPS connection (1): webhook.site:443
DEBUG:urllib3.connectionpool:https://webhook.site:443 "POST /38703b0d-ba51-49b8-9e8a-f9aaa82c4152 HTTP/1.1" 200 None
WARNING:googleapiclient.discovery_cache:file_cache is unavailable when using oauth2client >= 4.0.0 or google-auth
Traceback (most recent call last):
  File "C:\Users\sshho\anaconda3\envs\GmailAPI\lib\site-packages\googleapiclient\discovery_cache\file_cache.py", line 33, in <module>
    from oauth2client.contrib.locked_file import LockedFile
ModuleNotFoundError: No module named 'oauth2client'

During handling of the above exception, another exception occurred:

Traceback (most recent call last):
  File "C:\Users\sshho\anaconda3\envs\GmailAPI\lib\site-packages\googleapiclient\discovery_cache\file_cache.py", line 37, in <module>
    from oauth2client.locked_file import LockedFile
ModuleNotFoundError: No module named 'oauth2client'

During handling of the above exception, another exception occurred:

Traceback (most recent call last):
  File "C:\Users\sshho\anaconda3\envs\GmailAPI\lib\site-packages\googleapiclient\discovery_cache\__init__.py", line 44, in autodetect
    from . import file_cache
  File "C:\Users\sshho\anaconda3\envs\GmailAPI\lib\site-packages\googleapiclient\discovery_cache\file_cache.py", line 40, in <module>
    raise ImportError(
ImportError: file_cache is unavailable when using oauth2client >= 4.0.0 or google-auth
DEBUG:googleapiclient.discovery:URL being requested: GET https://www.googleapis.com/discovery/v1/apis/gmail/v1/rest
INFO:root:connected to Gmail API
DEBUG:googleapiclient.discovery:URL being requested: GET https://gmail.googleapis.com/gmail/v1/users/me/messages?labelIds=INBOX&alt=json
DEBUG:googleapiclient.discovery:URL being requested: GET https://gmail.googleapis.com/gmail/v1/users/me/messages/17589ab2ce4e1fc4?alt=json
DEBUG:googleapiclient.discovery:URL being requested: GET https://gmail.googleapis.com/gmail/v1/users/me/messages/17589601e24d1b0a?alt=json
DEBUG:googleapiclient.discovery:URL being requested: GET https://gmail.googleapis.com/gmail/v1/users/me/messages/17589488cedc2852?alt=json
DEBUG:googleapiclient.discovery:URL being requested: GET https://gmail.googleapis.com/gmail/v1/users/me/messages/175894336dfcbb46?alt=json
WARNING:googleapiclient.discovery_cache:file_cache is unavailable when using oauth2client >= 4.0.0 or google-auth
Traceback (most recent call last):
  File "C:\Users\sshho\anaconda3\envs\GmailAPI\lib\site-packages\googleapiclient\discovery_cache\file_cache.py", line 33, in <module>
    from oauth2client.contrib.locked_file import LockedFile
ModuleNotFoundError: No module named 'oauth2client'

During handling of the above exception, another exception occurred:

Traceback (most recent call last):
  File "C:\Users\sshho\anaconda3\envs\GmailAPI\lib\site-packages\googleapiclient\discovery_cache\file_cache.py", line 37, in <module>
    from oauth2client.locked_file import LockedFile
ModuleNotFoundError: No module named 'oauth2client'

During handling of the above exception, another exception occurred:

Traceback (most recent call last):
  File "C:\Users\sshho\anaconda3\envs\GmailAPI\lib\site-packages\googleapiclient\discovery_cache\__init__.py", line 44, in autodetect
    from . import file_cache
  File "C:\Users\sshho\anaconda3\envs\GmailAPI\lib\site-packages\googleapiclient\discovery_cache\file_cache.py", line 40, in <module>
    raise ImportError(
ImportError: file_cache is unavailable when using oauth2client >= 4.0.0 or google-auth
DEBUG:googleapiclient.discovery:URL being requested: GET https://www.googleapis.com/discovery/v1/apis/gmail/v1/rest
INFO:root:connected to Gmail API
DEBUG:googleapiclient.discovery:URL being requested: GET https://gmail.googleapis.com/gmail/v1/users/me/messages?labelIds=INBOX&alt=json
DEBUG:googleapiclient.discovery:URL being requested: GET https://gmail.googleapis.com/gmail/v1/users/me/messages/17589ab2ce4e1fc4?alt=json
DEBUG:googleapiclient.discovery:URL being requested: GET https://gmail.googleapis.com/gmail/v1/users/me/messages/17589601e24d1b0a?alt=json
DEBUG:googleapiclient.discovery:URL being requested: GET https://gmail.googleapis.com/gmail/v1/users/me/messages/17589488cedc2852?alt=json
DEBUG:googleapiclient.discovery:URL being requested: GET https://gmail.googleapis.com/gmail/v1/users/me/messages/175894336dfcbb46?alt=json
DEBUG:urllib3.connectionpool:Starting new HTTPS connection (1): webhook.site:443
DEBUG:urllib3.connectionpool:https://webhook.site:443 "POST /38703b0d-ba51-49b8-9e8a-f9aaa82c4152 HTTP/1.1" 200 None
WARNING:googleapiclient.discovery_cache:file_cache is unavailable when using oauth2client >= 4.0.0 or google-auth
Traceback (most recent call last):
  File "C:\Users\sshho\anaconda3\envs\GmailAPI\lib\site-packages\googleapiclient\discovery_cache\file_cache.py", line 33, in <module>
    from oauth2client.contrib.locked_file import LockedFile
ModuleNotFoundError: No module named 'oauth2client'

During handling of the above exception, another exception occurred:

Traceback (most recent call last):
  File "C:\Users\sshho\anaconda3\envs\GmailAPI\lib\site-packages\googleapiclient\discovery_cache\file_cache.py", line 37, in <module>
    from oauth2client.locked_file import LockedFile
ModuleNotFoundError: No module named 'oauth2client'

During handling of the above exception, another exception occurred:

Traceback (most recent call last):
  File "C:\Users\sshho\anaconda3\envs\GmailAPI\lib\site-packages\googleapiclient\discovery_cache\__init__.py", line 44, in autodetect
    from . import file_cache
  File "C:\Users\sshho\anaconda3\envs\GmailAPI\lib\site-packages\googleapiclient\discovery_cache\file_cache.py", line 40, in <module>
    raise ImportError(
ImportError: file_cache is unavailable when using oauth2client >= 4.0.0 or google-auth
DEBUG:googleapiclient.discovery:URL being requested: GET https://www.googleapis.com/discovery/v1/apis/gmail/v1/rest
INFO:root:connected to Gmail API
DEBUG:googleapiclient.discovery:URL being requested: GET https://gmail.googleapis.com/gmail/v1/users/me/messages?labelIds=INBOX&alt=json
DEBUG:googleapiclient.discovery:URL being requested: GET https://gmail.googleapis.com/gmail/v1/users/me/messages/17589ab2ce4e1fc4?alt=json
DEBUG:googleapiclient.discovery:URL being requested: GET https://gmail.googleapis.com/gmail/v1/users/me/messages/17589601e24d1b0a?alt=json
DEBUG:googleapiclient.discovery:URL being requested: GET https://gmail.googleapis.com/gmail/v1/users/me/messages/17589488cedc2852?alt=json
DEBUG:googleapiclient.discovery:URL being requested: GET https://gmail.googleapis.com/gmail/v1/users/me/messages/175894336dfcbb46?alt=json
DEBUG:googleapiclient.discovery:URL being requested: GET https://gmail.googleapis.com/gmail/v1/users/me/messages?labelIds=INBOX&alt=json
DEBUG:googleapiclient.discovery:URL being requested: GET https://gmail.googleapis.com/gmail/v1/users/me/messages/17589ab2ce4e1fc4?alt=json
DEBUG:googleapiclient.discovery:URL being requested: GET https://gmail.googleapis.com/gmail/v1/users/me/messages/17589601e24d1b0a?alt=json
DEBUG:googleapiclient.discovery:URL being requested: GET https://gmail.googleapis.com/gmail/v1/users/me/messages/17589488cedc2852?alt=json
DEBUG:googleapiclient.discovery:URL being requested: GET https://gmail.googleapis.com/gmail/v1/users/me/messages/175894336dfcbb46?alt=json
DEBUG:urllib3.connectionpool:Starting new HTTPS connection (1): webhook.site:443
DEBUG:urllib3.connectionpool:https://webhook.site:443 "POST /38703b0d-ba51-49b8-9e8a-f9aaa82c4152 HTTP/1.1" 200 None
DEBUG:googleapiclient.discovery:URL being requested: GET https://gmail.googleapis.com/gmail/v1/users/me/messages?labelIds=INBOX&alt=json
DEBUG:googleapiclient.discovery:URL being requested: GET https://gmail.googleapis.com/gmail/v1/users/me/messages/17589ab2ce4e1fc4?alt=json
DEBUG:googleapiclient.discovery:URL being requested: GET https://gmail.googleapis.com/gmail/v1/users/me/messages/17589601e24d1b0a?alt=json
DEBUG:googleapiclient.discovery:URL being requested: GET https://gmail.googleapis.com/gmail/v1/users/me/messages/17589488cedc2852?alt=json
DEBUG:googleapiclient.discovery:URL being requested: GET https://gmail.googleapis.com/gmail/v1/users/me/messages/175894336dfcbb46?alt=json
DEBUG:urllib3.connectionpool:Starting new HTTPS connection (1): webhook.site:443
DEBUG:urllib3.connectionpool:https://webhook.site:443 "POST /38703b0d-ba51-49b8-9e8a-f9aaa82c4152 HTTP/1.1" 200 None
DEBUG:googleapiclient.discovery:URL being requested: GET https://gmail.googleapis.com/gmail/v1/users/me/messages?labelIds=INBOX&alt=json
DEBUG:googleapiclient.discovery:URL being requested: GET https://gmail.googleapis.com/gmail/v1/users/me/messages/17589ab2ce4e1fc4?alt=json
DEBUG:googleapiclient.discovery:URL being requested: GET https://gmail.googleapis.com/gmail/v1/users/me/messages/17589601e24d1b0a?alt=json
DEBUG:googleapiclient.discovery:URL being requested: GET https://gmail.googleapis.com/gmail/v1/users/me/messages/17589488cedc2852?alt=json
DEBUG:googleapiclient.discovery:URL being requested: GET https://gmail.googleapis.com/gmail/v1/users/me/messages/175894336dfcbb46?alt=json
DEBUG:urllib3.connectionpool:Starting new HTTPS connection (1): webhook.site:443
DEBUG:urllib3.connectionpool:https://webhook.site:443 "POST /38703b0d-ba51-49b8-9e8a-f9aaa82c4152 HTTP/1.1" 200 None
DEBUG:googleapiclient.discovery:URL being requested: GET https://gmail.googleapis.com/gmail/v1/users/me/messages?labelIds=INBOX&alt=json
DEBUG:googleapiclient.discovery:URL being requested: GET https://gmail.googleapis.com/gmail/v1/users/me/messages/17589ab2ce4e1fc4?alt=json
DEBUG:googleapiclient.discovery:URL being requested: GET https://gmail.googleapis.com/gmail/v1/users/me/messages/17589601e24d1b0a?alt=json
DEBUG:googleapiclient.discovery:URL being requested: GET https://gmail.googleapis.com/gmail/v1/users/me/messages/17589488cedc2852?alt=json
DEBUG:googleapiclient.discovery:URL being requested: GET https://gmail.googleapis.com/gmail/v1/users/me/messages/175894336dfcbb46?alt=json
WARNING:googleapiclient.discovery_cache:file_cache is unavailable when using oauth2client >= 4.0.0 or google-auth
Traceback (most recent call last):
  File "C:\Users\sshho\anaconda3\envs\GmailAPI\lib\site-packages\googleapiclient\discovery_cache\file_cache.py", line 33, in <module>
    from oauth2client.contrib.locked_file import LockedFile
ModuleNotFoundError: No module named 'oauth2client'

During handling of the above exception, another exception occurred:

Traceback (most recent call last):
  File "C:\Users\sshho\anaconda3\envs\GmailAPI\lib\site-packages\googleapiclient\discovery_cache\file_cache.py", line 37, in <module>
    from oauth2client.locked_file import LockedFile
ModuleNotFoundError: No module named 'oauth2client'

During handling of the above exception, another exception occurred:

Traceback (most recent call last):
  File "C:\Users\sshho\anaconda3\envs\GmailAPI\lib\site-packages\googleapiclient\discovery_cache\__init__.py", line 44, in autodetect
    from . import file_cache
  File "C:\Users\sshho\anaconda3\envs\GmailAPI\lib\site-packages\googleapiclient\discovery_cache\file_cache.py", line 40, in <module>
    raise ImportError(
ImportError: file_cache is unavailable when using oauth2client >= 4.0.0 or google-auth
DEBUG:googleapiclient.discovery:URL being requested: GET https://www.googleapis.com/discovery/v1/apis/gmail/v1/rest
INFO:root:connected to Gmail API
DEBUG:googleapiclient.discovery:URL being requested: GET https://gmail.googleapis.com/gmail/v1/users/me/messages?labelIds=INBOX&alt=json
DEBUG:googleapiclient.discovery:URL being requested: GET https://gmail.googleapis.com/gmail/v1/users/me/messages/17589ab2ce4e1fc4?alt=json
DEBUG:googleapiclient.discovery:URL being requested: GET https://gmail.googleapis.com/gmail/v1/users/me/messages/17589601e24d1b0a?alt=json
DEBUG:googleapiclient.discovery:URL being requested: GET https://gmail.googleapis.com/gmail/v1/users/me/messages/17589488cedc2852?alt=json
DEBUG:googleapiclient.discovery:URL being requested: GET https://gmail.googleapis.com/gmail/v1/users/me/messages/175894336dfcbb46?alt=json
DEBUG:urllib3.connectionpool:Starting new HTTPS connection (1): webhook.site:443
DEBUG:urllib3.connectionpool:https://webhook.site:443 "POST /38703b0d-ba51-49b8-9e8a-f9aaa82c4152 HTTP/1.1" 200 None
WARNING:googleapiclient.discovery_cache:file_cache is unavailable when using oauth2client >= 4.0.0 or google-auth
Traceback (most recent call last):
  File "C:\Users\sshho\anaconda3\envs\GmailAPI\lib\site-packages\googleapiclient\discovery_cache\file_cache.py", line 33, in <module>
    from oauth2client.contrib.locked_file import LockedFile
ModuleNotFoundError: No module named 'oauth2client'

During handling of the above exception, another exception occurred:

Traceback (most recent call last):
  File "C:\Users\sshho\anaconda3\envs\GmailAPI\lib\site-packages\googleapiclient\discovery_cache\file_cache.py", line 37, in <module>
    from oauth2client.locked_file import LockedFile
ModuleNotFoundError: No module named 'oauth2client'

During handling of the above exception, another exception occurred:

Traceback (most recent call last):
  File "C:\Users\sshho\anaconda3\envs\GmailAPI\lib\site-packages\googleapiclient\discovery_cache\__init__.py", line 44, in autodetect
    from . import file_cache
  File "C:\Users\sshho\anaconda3\envs\GmailAPI\lib\site-packages\googleapiclient\discovery_cache\file_cache.py", line 40, in <module>
    raise ImportError(
ImportError: file_cache is unavailable when using oauth2client >= 4.0.0 or google-auth
DEBUG:googleapiclient.discovery:URL being requested: GET https://www.googleapis.com/discovery/v1/apis/gmail/v1/rest
INFO:root:connected to Gmail API
DEBUG:googleapiclient.discovery:URL being requested: GET https://gmail.googleapis.com/gmail/v1/users/me/messages?labelIds=INBOX&alt=json
DEBUG:googleapiclient.discovery:URL being requested: GET https://gmail.googleapis.com/gmail/v1/users/me/messages/17589ab2ce4e1fc4?alt=json
DEBUG:googleapiclient.discovery:URL being requested: GET https://gmail.googleapis.com/gmail/v1/users/me/messages/17589601e24d1b0a?alt=json
DEBUG:googleapiclient.discovery:URL being requested: GET https://gmail.googleapis.com/gmail/v1/users/me/messages/17589488cedc2852?alt=json
DEBUG:googleapiclient.discovery:URL being requested: GET https://gmail.googleapis.com/gmail/v1/users/me/messages/175894336dfcbb46?alt=json
DEBUG:urllib3.connectionpool:Starting new HTTPS connection (1): webhook.site:443
DEBUG:urllib3.connectionpool:https://webhook.site:443 "POST /38703b0d-ba51-49b8-9e8a-f9aaa82c4152 HTTP/1.1" 200 None
DEBUG:googleapiclient.discovery:URL being requested: GET https://gmail.googleapis.com/gmail/v1/users/me/messages?labelIds=INBOX&alt=json
DEBUG:googleapiclient.discovery:URL being requested: GET https://gmail.googleapis.com/gmail/v1/users/me/messages/17589ab2ce4e1fc4?alt=json
DEBUG:googleapiclient.discovery:URL being requested: GET https://gmail.googleapis.com/gmail/v1/users/me/messages/17589601e24d1b0a?alt=json
DEBUG:googleapiclient.discovery:URL being requested: GET https://gmail.googleapis.com/gmail/v1/users/me/messages/17589488cedc2852?alt=json
DEBUG:googleapiclient.discovery:URL being requested: GET https://gmail.googleapis.com/gmail/v1/users/me/messages/175894336dfcbb46?alt=json
DEBUG:urllib3.connectionpool:Starting new HTTPS connection (1): webhook.site:443
DEBUG:urllib3.connectionpool:https://webhook.site:443 "POST /38703b0d-ba51-49b8-9e8a-f9aaa82c4152 HTTP/1.1" 200 None
